<?xml version='1.0'?>
<robot name="OAbot">
	<link name = "base"/>
	<link name = "left_wheel"/>
	<link name = "right_wheel"/>

	<joint name="base_to_left_wheel" type="continuous">
		<parent link = "base"/>
		<child link = "left_wheel"/>
		<origin xyz="0 0.5 0" rpy="1.732 0 0"/>
		<axis xyz="0 1 0" />
	</joint>
	<joint name="base_to_right_wheel" type="continuous">
		<parent link = "base"/>
		<child link = "right_wheel"/>
		<origin xyz="0 -0.5 0" rpy="1.732 0 0"/>
		<axis xyz="0 1 0" />
	</joint>
</robot>	
